
Epoch  0: 0.76, 0.56, 0.73, 0.79
Process wandb_internal:
Traceback (most recent call last):
  File "/opt/conda/lib/python3.9/multiprocessing/process.py", line 315, in _bootstrap
    self.run()
  File "/opt/conda/lib/python3.9/multiprocessing/process.py", line 108, in run
    self._target(*self._args, **self._kwargs)
  File "/opt/conda/lib/python3.9/site-packages/wandb/sdk/internal/internal.py", line 162, in wandb_internal
    thread.join()
  File "/opt/conda/lib/python3.9/threading.py", line 1053, in join
    self._wait_for_tstate_lock()
  File "/opt/conda/lib/python3.9/threading.py", line 1069, in _wait_for_tstate_lock
    elif lock.acquire(block, timeout):
KeyboardInterrupt
Exception in thread ChkStopThr:
Traceback (most recent call last):
  File "/opt/conda/lib/python3.9/threading.py", line 973, in _bootstrap_inner
    self.run()
  File "/opt/conda/lib/python3.9/threading.py", line 910, in run
    self._target(*self._args, **self._kwargs)
  File "/opt/conda/lib/python3.9/site-packages/wandb/sdk/wandb_run.py", line 167, in check_status
    status_response = self._interface.communicate_stop_status()
  File "/opt/conda/lib/python3.9/site-packages/wandb/sdk/interface/interface.py", line 114, in communicate_stop_status
    resp = self._communicate_stop_status(status)
  File "/opt/conda/lib/python3.9/site-packages/wandb/sdk/interface/interface_shared.py", line 387, in _communicate_stop_status
    resp = self._communicate(req, local=True)
  File "/opt/conda/lib/python3.9/site-packages/wandb/sdk/interface/interface_shared.py", line 222, in _communicate
    return self._communicate_async(rec, local=local).get(timeout=timeout)
  File "/opt/conda/lib/python3.9/site-packages/wandb/sdk/interface/interface_shared.py", line 227, in _communicate_async
    raise Exception("The wandb backend process has shutdown")
Exception: The wandb backend process has shutdownException in thread NetStatThr:
Traceback (most recent call last):
  File "/opt/conda/lib/python3.9/threading.py", line 973, in _bootstrap_inner
    self.run()
  File "/opt/conda/lib/python3.9/threading.py", line 910, in run
    self._target(*self._args, **self._kwargs)
  File "/opt/conda/lib/python3.9/site-packages/wandb/sdk/wandb_run.py", line 149, in check_network_status
    status_response = self._interface.communicate_network_status()
  File "/opt/conda/lib/python3.9/site-packages/wandb/sdk/interface/interface.py", line 125, in communicate_network_status
    resp = self._communicate_network_status(status)
  File "/opt/conda/lib/python3.9/site-packages/wandb/sdk/interface/interface_shared.py", line 397, in _communicate_network_status
    resp = self._communicate(req, local=True)
  File "/opt/conda/lib/python3.9/site-packages/wandb/sdk/interface/interface_shared.py", line 222, in _communicate
    return self._communicate_async(rec, local=local).get(timeout=timeout)
  File "/opt/conda/lib/python3.9/site-packages/wandb/sdk/interface/interface_shared.py", line 227, in _communicate_async
    raise Exception("The wandb backend process has shutdown")
Exception: The wandb backend process has shutdown
Error in callback <function _WandbInit._resume_backend at 0x7f8652ec2ee0> (for pre_run_cell):
######## complexity: 100, dropout rate: 0
Problem at: /tmp/ipykernel_84/1103861343.py 15 <module>
Traceback (most recent call last):
  File "/opt/conda/lib/python3.9/site-packages/wandb/sdk/wandb_init.py", line 954, in init
    run = wi.init()
  File "/opt/conda/lib/python3.9/site-packages/wandb/sdk/wandb_init.py", line 471, in init
    self._wl._global_run_stack[-1].finish()
  File "/opt/conda/lib/python3.9/site-packages/wandb/sdk/wandb_run.py", line 1538, in finish
    tel.feature.finish = True
  File "/opt/conda/lib/python3.9/site-packages/wandb/sdk/lib/telemetry.py", line 43, in __exit__
    self._run._telemetry_callback(self._obj)
  File "/opt/conda/lib/python3.9/site-packages/wandb/sdk/wandb_run.py", line 470, in _telemetry_callback
    self._telemetry_flush()
  File "/opt/conda/lib/python3.9/site-packages/wandb/sdk/wandb_run.py", line 481, in _telemetry_flush
    self._backend.interface._publish_telemetry(self._telemetry_obj)
  File "/opt/conda/lib/python3.9/site-packages/wandb/sdk/interface/interface_shared.py", line 73, in _publish_telemetry
    self._publish(rec)
  File "/opt/conda/lib/python3.9/site-packages/wandb/sdk/interface/interface_queue.py", line 49, in _publish
    raise Exception("The wandb backend process has shutdown")
Exception: The wandb backend process has shutdown
[34m[1mwandb[39m[22m: [32m[41mERROR[39m[49m Abnormal program exit
Error in callback <function _WandbInit._pause_backend at 0x7f863f180a60> (for post_run_cell):
Error in callback <function _WandbInit._resume_backend at 0x7f8652ec2ee0> (for pre_run_cell):
######## complexity: 100, dropout rate: 0
Traceback (most recent call last):
  File "/opt/conda/lib/python3.9/site-packages/wandb/sdk/wandb_init.py", line 951, in init
    wi.setup(kwargs)
  File "/opt/conda/lib/python3.9/site-packages/wandb/sdk/wandb_init.py", line 143, in setup
    tel.feature.set_init_tags = True
  File "/opt/conda/lib/python3.9/site-packages/wandb/sdk/lib/telemetry.py", line 43, in __exit__
    self._run._telemetry_callback(self._obj)
  File "/opt/conda/lib/python3.9/site-packages/wandb/sdk/wandb_run.py", line 470, in _telemetry_callback
    self._telemetry_flush()
  File "/opt/conda/lib/python3.9/site-packages/wandb/sdk/wandb_run.py", line 481, in _telemetry_flush
    self._backend.interface._publish_telemetry(self._telemetry_obj)
  File "/opt/conda/lib/python3.9/site-packages/wandb/sdk/interface/interface_shared.py", line 73, in _publish_telemetry
    self._publish(rec)
  File "/opt/conda/lib/python3.9/site-packages/wandb/sdk/interface/interface_queue.py", line 49, in _publish
    raise Exception("The wandb backend process has shutdown")
Exception: The wandb backend process has shutdown
Error in callback <function _WandbInit._pause_backend at 0x7f863f180a60> (for post_run_cell):
[34m[1mwandb[39m[22m: [32m[41mERROR[39m[49m Abnormal program exit